<?xml version="1.0"?>
<sdf version="1.8" xmlns:xacro="http://ros.org/wiki/xacro">
  <model name="wheeltec_mini_mec" xmlns:ignition="http://ignitionrobotics.org/schema"
    canonical_link='base_link'>

    <link name="base_footprint" />

    <link name="base_link">
      <pose>0 0 0.0975 0 0 0</pose>
      <inertial>
        <mass>1.26</mass>
        <inertia>
          <ixx>0.00391125</ixx>
          <ixy>0</ixy>
          <ixz>0</ixz>
          <iyy>0.007972125</iyy>
          <iyz>0</iyz>
          <izz>0.011248125</izz>
        </inertia>
      </inertial>
      <visual name='visual'>
        <pose>0.0120 0 -0.0505 0 0 0</pose>
        <geometry>
          <!-- <box>
              <size>0.27 0.185 0.055</size>
            </box> -->
          <mesh>
            <uri>
              model://ros_gz_example_description/models/wheeltec_mini_mec/meshes/base_link.STL
            </uri>
          </mesh>
        </geometry>
        <material>
          <ambient>0.5 0.5 1.0 1</ambient>
          <diffuse>0.5 0.5 1.0 1</diffuse>
          <specular>0.0 0.0 1.0 1</specular>
        </material>
      </visual>
      <collision name='collision'>
        <geometry>
          <box>
            <size>0.27 0.185 0.055</size>
          </box>
        </geometry>
      </collision>
    </link>

    <link name="left_wheel_link">
      <pose>-0.085 0.0975 0.0375 -1.57 0 0</pose>
      <inertial>
        <mass>0.41</mass>
        <inertia>
          <ixx>0.000179127291666667</ixx>
          <ixy>0</ixy>
          <ixz>0</ixz>
          <iyy>0.000179127291666667</iyy>
          <iyz>0</iyz>
          <izz>0.00028828125</izz>
        </inertia>
      </inertial>
      <visual name='visual'>
        <pose>0 0 -0.01625 1.5707 0 0</pose>
        <geometry>
          <!-- <sphere>
              <radius>0.0375</radius>
            </sphere> -->
          <!-- scale mesh to radius == 0.0375 -->
          <mesh>
            <!-- <uri>https://fuel.gazebosim.org/1.0/OpenRobotics/models/Mecanum
                lift/tip/files/meshes/mecanum_wheel_right.STL</uri> -->
            <uri>
              model://ros_gz_example_description/models/wheeltec_mini_mec/meshes/left_rear_wheel_link.STL
            </uri>
            <!-- <scale>0.00075 0.00075 0.00075</scale> -->
          </mesh>
        </geometry>
        <material>
          <ambient>0.2 0.2 0.2 1</ambient>
          <diffuse>0.2 0.2 0.2 1</diffuse>
          <specular>0.2 0.2 0.2 1</specular>
        </material>
      </visual>
      <collision name='collision'>
        <geometry>
          <sphere>
            <radius>0.0375</radius>
          </sphere>
        </geometry>
        <surface>
          <friction>
            <ode>
              <mu>1.0</mu>
              <mu2>0.0</mu2>
              <fdir1 ignition:expressed_in="base_link">1 1 0</fdir1>
            </ode>
          </friction>
        </surface>
      </collision>
    </link>

    <link name="right_wheel_link">
      <pose>-0.085 -0.0975 0.0375 -1.57 0 0</pose>
      <inertial>
        <mass>0.41</mass>
        <inertia>
          <ixx>0.000179127291666667</ixx>
          <ixy>0</ixy>
          <ixz>0</ixz>
          <iyy>0.000179127291666667</iyy>
          <iyz>0</iyz>
          <izz>0.00028828125</izz>
        </inertia>
      </inertial>
      <visual name='visual'>
        <pose>0 0 0.01625 1.5707 0 0</pose>
        <geometry>
          <!-- <sphere>
              <radius>0.0375</radius>
            </sphere> -->
          <!-- scale mesh to radius == 0.0375 -->
          <mesh>
            <!-- <uri>https://fuel.gazebosim.org/1.0/OpenRobotics/models/Mecanum
                lift/tip/files/meshes/mecanum_wheel_left.STL</uri> -->
            <uri>
              model://ros_gz_example_description/models/wheeltec_mini_mec/meshes/right_rear_wheel_link.STL
            </uri>
            <!-- <scale>0.00075 0.00075 0.00075</scale> -->
          </mesh>
        </geometry>
        <material>
          <ambient>0.2 0.2 0.2 1</ambient>
          <diffuse>0.2 0.2 0.2 1</diffuse>
          <specular>0.2 0.2 0.2 1</specular>
        </material>
      </visual>
      <collision name='collision'>
        <geometry>
          <sphere>
            <radius>0.0375</radius>
          </sphere>
        </geometry>
        <surface>
          <friction>
            <ode>
              <mu>1.0</mu>
              <mu2>0.0</mu2>
              <fdir1 ignition:expressed_in="base_link">1 -1 0</fdir1>
            </ode>
          </friction>
        </surface>
      </collision>
    </link>

    <link name="left_front_link">
      <pose>0.085 0.0975 0.0375 -1.57 0 0</pose>
      <inertial>
        <mass>0.41</mass>
        <inertia>
          <ixx>0.000179127291666667</ixx>
          <ixy>0</ixy>
          <ixz>0</ixz>
          <iyy>0.000179127291666667</iyy>
          <iyz>0</iyz>
          <izz>0.00028828125</izz>
        </inertia>
      </inertial>
      <visual name='visual'>
        <pose>0 0 -0.01625 1.5707 0 0</pose>
        <geometry>
          <!-- <sphere>
              <radius>0.0375</radius>
            </sphere> -->
          <!-- scale mesh to radius == 0.0375 -->
          <mesh>
            <!-- <uri>https://fuel.gazebosim.org/1.0/OpenRobotics/models/Mecanum
                lift/tip/files/meshes/mecanum_wheel_left.STL</uri> -->
            <uri>
              model://ros_gz_example_description/models/wheeltec_mini_mec/meshes/left_front_wheel_link.STL
            </uri>
            <!-- <scale>0.00075 0.00075 0.00075</scale> -->
          </mesh>
        </geometry>
        <material>
          <ambient>0.2 0.2 0.2 1</ambient>
          <diffuse>0.2 0.2 0.2 1</diffuse>
          <specular>0.2 0.2 0.2 1</specular>
        </material>
      </visual>
      <collision name='collision'>
        <geometry>
          <sphere>
            <radius>0.0375</radius>
          </sphere>
        </geometry>
        <surface>
          <friction>
            <ode>
              <mu>1.0</mu>
              <mu2>0.0</mu2>
              <fdir1 ignition:expressed_in="base_link">1 -1 0</fdir1>
            </ode>
          </friction>
        </surface>
      </collision>
    </link>

    <link name="right_front_link">
      <pose>0.085 -0.0975 0.0375 -1.57 0 0</pose>
      <inertial>
        <mass>0.41</mass>
        <inertia>
          <ixx>0.000179127291666667</ixx>
          <ixy>0</ixy>
          <ixz>0</ixz>
          <iyy>0.000179127291666667</iyy>
          <iyz>0</iyz>
          <izz>0.00028828125</izz>
        </inertia>
      </inertial>
      <visual name='visual'>
        <pose>0 0 0.01625 1.5707 0 0</pose>
        <geometry>
          <!-- <sphere>
              <radius>0.0375</radius>
            </sphere> -->
          <!-- scale mesh to radius == 0.0375 -->
          <mesh>
            <!-- <uri>https://fuel.gazebosim.org/1.0/OpenRobotics/models/Mecanum
                lift/tip/files/meshes/mecanum_wheel_right.STL</uri> -->
            <uri>
              model://ros_gz_example_description/models/wheeltec_mini_mec/meshes/right_front_wheel_link.STL
            </uri>
            <!-- <scale>0.00075 0.00075 0.00075</scale> -->
          </mesh>
        </geometry>
        <material>
          <ambient>0.2 0.2 0.2 1</ambient>
          <diffuse>0.2 0.2 0.2 1</diffuse>
          <specular>0.2 0.2 0.2 1</specular>
        </material>
      </visual>
      <collision name='collision'>
        <geometry>
          <sphere>
            <radius>0.0375</radius>
          </sphere>
        </geometry>
        <surface>
          <friction>
            <ode>
              <mu>1.0</mu>
              <mu2>0.0</mu2>
              <fdir1 ignition:expressed_in="base_link">1 1 0</fdir1>
            </ode>
          </friction>
        </surface>
      </collision>
    </link>

    <link name="camera_rgb_frame">
      <pose relative_to="camera_link">0 0 0 -1.570795 0 -1.570795</pose>
    </link>

    <link name="camera_link">
      <pose>0.135 0 0.145 0 -0.523599 0</pose>
      <inertial>
        <mass>0.1</mass>
        <inertia>
          <ixx>0.000166667</ixx>
          <iyy>0.000166667</iyy>
          <izz>0.000166667</izz>
        </inertia>
      </inertial>
      <collision name="collision">
        <geometry>
          <box>
            <size>0.018 0.045 0.04</size>
          </box>
        </geometry>
      </collision>
      <visual name="visual">
        <geometry>
          <box>
            <size>0.018 0.045 0.04</size>
          </box>
        </geometry>
      </visual>
      <sensor name="camera" type="camera">
        <always_on>true</always_on>
        <visualize>true</visualize>
        <update_rate>30</update_rate>
        <topic>camera/image_raw</topic>
        <gz_frame_id>camera_rgb_frame</gz_frame_id>
        <camera>
          <camera_info_topic>camera/camera_info</camera_info_topic>
          <horizontal_fov>1.02974</horizontal_fov>
          <image>
            <width>1920</width>
            <height>1080</height>
            <format>R8G8B8</format>
          </image>
          <clip>
            <near>0.02</near>
            <far>300</far>
          </clip>
          <noise>
            <type>gaussian</type>
            <!-- Noise is sampled independently per pixel on each frame.
                  That pixel's noise value is added to each of its color
                  channels, which at that point lie in the range [0,1]. -->
            <mean>0.0</mean>
            <stddev>0.007</stddev>
          </noise>
        </camera>
      </sensor>
    </link>

    <link name="base_scan">
      <pose>0 0 0.186 0 0 0</pose>
      <inertial>
        <mass>0.1</mass>
        <inertia>
          <ixx>0.000166667</ixx>
          <iyy>0.000166667</iyy>
          <izz>0.000166667</izz>
        </inertia>
      </inertial>
      <collision name="collision">
        <geometry>
          <cylinder>
            <radius>0.0275</radius>
            <length>0.06</length>
          </cylinder>
        </geometry>
      </collision>
      <visual name="visual">
        <geometry>
          <cylinder>
            <radius>0.0275</radius>
            <length>0.06</length>
          </cylinder>
        </geometry>
      </visual>
      <sensor name="lslidar_n10p" type="gpu_lidar">
        <always_on>true</always_on>
        <visualize>true</visualize>
        <update_rate>10</update_rate>
        <topic>scan</topic>
        <gz_frame_id>base_scan</gz_frame_id>
        <lidar>
          <scan>
            <horizontal>
              <samples>360</samples>
              <resolution>1.000000</resolution>
              <min_angle>0.000000</min_angle>
              <max_angle>6.2832</max_angle>
            </horizontal>
          </scan>
          <range>
            <min>0.08</min>
            <max>10.0</max>
            <resolution>0.01</resolution>
          </range>
          <noise>
            <type>gaussian</type>
            <mean>0.0</mean>
            <stddev>0.01</stddev>
          </noise>
        </lidar>
      </sensor>
    </link>

    <link name="imu_link">
      <pose relative_to="base_link">0 0 0 0 0 0</pose>
      <sensor name="imu_sensor" type="imu">
        <always_on>1</always_on>
        <update_rate>50</update_rate>
        <visualize>true</visualize>
        <topic>imu</topic>
      </sensor>
    </link>

    <!-- joint relationship -->
    <joint name="base_joint" type="fixed">
      <parent>base_link</parent>
      <child>base_footprint</child>
    </joint>

    <joint name="left_wheel_joint" type="revolute">
      <parent>base_link</parent>
      <child>left_wheel_link</child>
      <axis>
        <xyz>0 0 1</xyz>
        <limit>
          <lower>-1.79769e+308</lower>
          <upper>1.79769e+308</upper>
        </limit>
      </axis>
    </joint>

    <joint name="right_wheel_joint" type="revolute">
      <parent>base_link</parent>
      <child>right_wheel_link</child>
      <axis>
        <xyz>0 0 1</xyz>
        <limit>
          <lower>-1.79769e+308</lower>
          <upper>1.79769e+308</upper>
        </limit>
      </axis>
    </joint>

    <joint name="left_front_joint" type="revolute">
      <parent>base_link</parent>
      <child>left_front_link</child>
      <axis>
        <xyz>0 0 1</xyz>
        <limit>
          <lower>-1.79769e+308</lower>
          <upper>1.79769e+308</upper>
        </limit>
      </axis>
    </joint>

    <joint name="right_front_joint" type="revolute">
      <parent>base_link</parent>
      <child>right_front_link</child>
      <axis>
        <xyz>0 0 1</xyz>
        <limit>
          <lower>-1.79769e+308</lower>
          <upper>1.79769e+308</upper>
        </limit>
      </axis>
    </joint>

    <joint name="camera_joint" type="fixed">
      <parent>base_link</parent>
      <child>camera_link</child>
    </joint>

    <joint name="camera_rgb_joint" type="fixed">
      <parent>camera_link</parent>
      <child>camera_rgb_frame</child>
    </joint>

    <joint name="lidar_joint" type="fixed">
      <parent>base_link</parent>
      <child>base_scan</child>
    </joint>

    <joint name="imu_joint" type="fixed">
      <parent>base_link</parent>
      <child>imu_link</child>
    </joint>

    <plugin
      filename="ignition-gazebo-mecanum-drive-system"
      name="ignition::gazebo::systems::MecanumDrive">
      <front_left_joint>left_front_joint</front_left_joint>
      <front_right_joint>right_front_joint</front_right_joint>
      <back_left_joint>left_wheel_joint</back_left_joint>
      <back_right_joint>right_wheel_joint</back_right_joint>
      <wheel_separation>0.195</wheel_separation>
      <wheelbase>0.17</wheelbase>
      <wheel_radius>0.0375</wheel_radius>
      <min_acceleration>-1</min_acceleration>
      <max_acceleration>1</max_acceleration>
    </plugin>

    <plugin
      filename="ignition-gazebo-joint-state-publisher-system"
      name="ignition::gazebo::systems::JointStatePublisher">
      <topic>joint_states</topic>
    </plugin>

  </model>
</sdf>