<?xml version="1.0"?>
<sdf version="1.8">
  <world name="wheeltec_mini_mec_world">

    <physics name="1ms" type="ignored">
      <max_step_size>0.001</max_step_size>
      <real_time_factor>1.0</real_time_factor>
    </physics>
    <plugin
      filename="ignition-gazebo-physics-system"
      name="gz::sim::systems::Physics">
    </plugin>
    <plugin
      filename="ignition-gazebo-user-commands-system"
      name="gz::sim::systems::UserCommands">
    </plugin>
    <plugin
      filename="ignition-gazebo-scene-broadcaster-system"
      name="gz::sim::systems::SceneBroadcaster">
    </plugin>
    <plugin
      filename="ignition-gazebo-sensors-system"
      name="gz::sim::systems::Sensors">
      <render_engine>ogre2</render_engine>
    </plugin>

    <light type="directional" name="sun">
      <cast_shadows>true</cast_shadows>
      <pose>0 0 10 0 0 0</pose>
      <diffuse>1 1 1 1</diffuse>
      <specular>0.5 0.5 0.5 1</specular>
      <attenuation>
        <range>1000</range>
        <constant>0.9</constant>
        <linear>0.01</linear>
        <quadratic>0.001</quadratic>
      </attenuation>
      <direction>-0.5 0.1 -0.9</direction>
    </light>

    <model name="ground_plane">
      <static>true</static>
      <link name="link">
        <collision name="collision">
          <geometry>
            <plane>
              <normal>0 0 1</normal>
              <size>100 100</size>
            </plane>
          </geometry>
          <surface>
            <friction>
              <ode>
                <mu>50</mu>
              </ode>
            </friction>
          </surface>
        </collision>
        <visual name="visual">
          <geometry>
            <plane>
              <normal>0 0 1</normal>
              <size>100 100</size>
            </plane>
          </geometry>
          <material>
            <ambient>0.8 0.8 0.8 1</ambient>
            <diffuse>0.8 0.8 0.8 1</diffuse>
            <specular>0.8 0.8 0.8 1</specular>
          </material>
        </visual>
      </link>
    </model>

    <model name="wheeltec_mini_mec">

      <link name="base_footprint" />

      <link name="base_link">
        <pose>0 0 0.0975 0 0 0</pose>
        <inertial>
          <mass>1.26</mass>
          <inertia>
            <ixx>0.00391125</ixx>
            <ixy>0</ixy>
            <ixz>0</ixz>
            <iyy>0.007972125</iyy>
            <iyz>0</iyz>
            <izz>0.011248125</izz>
          </inertia>
        </inertial>
        <visual name='visual'>
          <geometry>
            <box>
              <size>0.27 0.185 0.055</size>
            </box>
          </geometry>
          <material>
            <ambient>0.5 0.5 1.0 1</ambient>
            <diffuse>0.5 0.5 1.0 1</diffuse>
            <specular>0.0 0.0 1.0 1</specular>
          </material>
        </visual>
        <collision name='collision'>
          <geometry>
            <box>
              <size>0.27 0.185 0.055</size>
            </box>
          </geometry>
        </collision>
      </link>

      <link name="left_wheel_link">
        <pose>-0.085 0.0975 0.0375 -1.57 0 0</pose>
        <inertial>
          <mass>0.41</mass>
          <inertia>
            <ixx>0.000179127291666667</ixx>
            <ixy>0</ixy>
            <ixz>0</ixz>
            <iyy>0.000179127291666667</iyy>
            <iyz>0</iyz>
            <izz>0.00028828125</izz>
          </inertia>
        </inertial>
        <visual name='visual'>
          <pose>0 0 0 1.5707 0 0</pose>
          <geometry>
            <!-- <sphere>
              <radius>0.0375</radius>
            </sphere> -->
            <!-- scale mesh to radius == 0.0375 -->
            <mesh>
              <uri>https://fuel.gazebosim.org/1.0/OpenRobotics/models/Mecanum
                lift/tip/files/meshes/mecanum_wheel_right.STL</uri>
              <scale>0.00075 0.00075 0.00075</scale>
            </mesh>
          </geometry>
          <material>
            <ambient>0.2 0.2 0.2 1</ambient>
            <diffuse>0.2 0.2 0.2 1</diffuse>
            <specular>0.2 0.2 0.2 1</specular>
          </material>
        </visual>
        <collision name='collision'>
          <geometry>
            <sphere>
              <radius>0.0375</radius>
            </sphere>
          </geometry>
          <surface>
            <friction>
              <ode>
                <mu>1.0</mu>
                <mu2>0.0</mu2>
                <fdir1 ignition:expressed_in="base_link">1 1 0</fdir1>
              </ode>
            </friction>
          </surface>
        </collision>
      </link>

      <link name="right_wheel_link">
        <pose>-0.085 -0.0975 0.0375 -1.57 0 0</pose>
        <inertial>
          <mass>0.41</mass>
          <inertia>
            <ixx>0.000179127291666667</ixx>
            <ixy>0</ixy>
            <ixz>0</ixz>
            <iyy>0.000179127291666667</iyy>
            <iyz>0</iyz>
            <izz>0.00028828125</izz>
          </inertia>
        </inertial>
        <visual name='visual'>
          <pose>0 0 0 1.5707 0 0</pose>
          <geometry>
            <!-- <sphere>
              <radius>0.0375</radius>
            </sphere> -->
            <!-- scale mesh to radius == 0.0375 -->
            <mesh>
              <uri>https://fuel.gazebosim.org/1.0/OpenRobotics/models/Mecanum
                lift/tip/files/meshes/mecanum_wheel_left.STL</uri>
              <scale>0.00075 0.00075 0.00075</scale>
            </mesh>
          </geometry>
          <material>
            <ambient>0.2 0.2 0.2 1</ambient>
            <diffuse>0.2 0.2 0.2 1</diffuse>
            <specular>0.2 0.2 0.2 1</specular>
          </material>
        </visual>
        <collision name='collision'>
          <geometry>
            <sphere>
              <radius>0.0375</radius>
            </sphere>
          </geometry>
          <surface>
            <friction>
              <ode>
                <mu>1.0</mu>
                <mu2>0.0</mu2>
                <fdir1 ignition:expressed_in="base_link">1 -1 0</fdir1>
              </ode>
            </friction>
          </surface>
        </collision>
      </link>

      <link name="left_front_link">
        <pose>0.085 0.0975 0.0375 -1.57 0 0</pose>
        <inertial>
          <mass>0.41</mass>
          <inertia>
            <ixx>0.000179127291666667</ixx>
            <ixy>0</ixy>
            <ixz>0</ixz>
            <iyy>0.000179127291666667</iyy>
            <iyz>0</iyz>
            <izz>0.00028828125</izz>
          </inertia>
        </inertial>
        <visual name='visual'>
          <pose>0 0 0 1.5707 0 0</pose>
          <geometry>
            <!-- <sphere>
              <radius>0.0375</radius>
            </sphere> -->
            <!-- scale mesh to radius == 0.0375 -->
            <mesh>
              <uri>https://fuel.gazebosim.org/1.0/OpenRobotics/models/Mecanum
                lift/tip/files/meshes/mecanum_wheel_left.STL</uri>
              <scale>0.00075 0.00075 0.00075</scale>
            </mesh>
          </geometry>
          <material>
            <ambient>0.2 0.2 0.2 1</ambient>
            <diffuse>0.2 0.2 0.2 1</diffuse>
            <specular>0.2 0.2 0.2 1</specular>
          </material>
        </visual>
        <collision name='collision'>
          <geometry>
            <sphere>
              <radius>0.0375</radius>
            </sphere>
          </geometry>
          <surface>
            <friction>
              <ode>
                <mu>1.0</mu>
                <mu2>0.0</mu2>
                <fdir1 ignition:expressed_in="base_link">1 -1 0</fdir1>
              </ode>
            </friction>
          </surface>
        </collision>
      </link>

      <link name="right_front_link">
        <pose>0.085 -0.0975 0.0375 -1.57 0 0</pose>
        <inertial>
          <mass>0.41</mass>
          <inertia>
            <ixx>0.000179127291666667</ixx>
            <ixy>0</ixy>
            <ixz>0</ixz>
            <iyy>0.000179127291666667</iyy>
            <iyz>0</iyz>
            <izz>0.00028828125</izz>
          </inertia>
        </inertial>
        <visual name='visual'>
          <pose>0 0 0 1.5707 0 0</pose>
          <geometry>
            <!-- <sphere>
              <radius>0.0375</radius>
            </sphere> -->
            <!-- scale mesh to radius == 0.0375 -->
            <mesh>
              <uri>https://fuel.gazebosim.org/1.0/OpenRobotics/models/Mecanum
                lift/tip/files/meshes/mecanum_wheel_right.STL</uri>
              <scale>0.00075 0.00075 0.00075</scale>
            </mesh>
          </geometry>
          <material>
            <ambient>0.2 0.2 0.2 1</ambient>
            <diffuse>0.2 0.2 0.2 1</diffuse>
            <specular>0.2 0.2 0.2 1</specular>
          </material>
        </visual>
        <collision name='collision'>
          <geometry>
            <sphere>
              <radius>0.0375</radius>
            </sphere>
          </geometry>
          <surface>
            <friction>
              <ode>
                <mu>1.0</mu>
                <mu2>0.0</mu2>
                <fdir1 ignition:expressed_in="base_link">1 1 0</fdir1>
              </ode>
            </friction>
          </surface>
        </collision>
      </link>

      <link name="camera_rgb_frame" />

      <link name="camera_link">
        <pose>0.135 0 0.145 0 -0.523599 0</pose>
        <inertial>
          <mass>0.1</mass>
          <inertia>
            <ixx>0.000166667</ixx>
            <iyy>0.000166667</iyy>
            <izz>0.000166667</izz>
          </inertia>
        </inertial>
        <collision name="collision">
          <geometry>
            <box>
              <size>0.018 0.045 0.04</size>
            </box>
          </geometry>
        </collision>
        <visual name="visual">
          <geometry>
            <box>
              <size>0.018 0.045 0.04</size>
            </box>
          </geometry>
        </visual>
        <sensor name="camera" type="camera">
          <always_on>true</always_on>
          <visualize>true</visualize>
          <update_rate>30</update_rate>
          <topic>camera/image_raw</topic>
          <gz_frame_id>camera_rgb_frame</gz_frame_id>
          <camera>
            <camera_info_topic>camera/camera_info</camera_info_topic>
            <horizontal_fov>1.02974</horizontal_fov>
            <image>
              <width>1920</width>
              <height>1080</height>
              <format>R8G8B8</format>
            </image>
            <clip>
              <near>0.02</near>
              <far>300</far>
            </clip>
            <noise>
              <type>gaussian</type>
              <!-- Noise is sampled independently per pixel on each frame.
                  That pixel's noise value is added to each of its color
                  channels, which at that point lie in the range [0,1]. -->
              <mean>0.0</mean>
              <stddev>0.007</stddev>
            </noise>
          </camera>
        </sensor>
      </link>

      <link name="base_scan">
        <pose>0 0 0.186 0 0 0</pose>
        <inertial>
          <mass>0.1</mass>
          <inertia>
            <ixx>0.000166667</ixx>
            <iyy>0.000166667</iyy>
            <izz>0.000166667</izz>
          </inertia>
        </inertial>
        <collision name="collision">
          <geometry>
            <cylinder>
              <radius>0.0275</radius>
              <length>0.06</length>
            </cylinder>
          </geometry>
        </collision>
        <visual name="visual">
          <geometry>
            <cylinder>
              <radius>0.0275</radius>
              <length>0.06</length>
            </cylinder>
          </geometry>
        </visual>
        <sensor name="lslidar_n10p" type="gpu_lidar">
          <always_on>true</always_on>
          <visualize>true</visualize>
          <update_rate>10</update_rate>
          <topic>scan</topic>
          <gz_frame_id>base_scan</gz_frame_id>
          <lidar>
            <scan>
              <horizontal>
                <samples>360</samples>
                <resolution>1.000000</resolution>
                <min_angle>0.000000</min_angle>
                <max_angle>6.2832</max_angle>
              </horizontal>
            </scan>
            <range>
              <min>0.08</min>
              <max>10.0</max>
              <resolution>0.01</resolution>
            </range>
            <noise>
              <type>gaussian</type>
              <mean>0.0</mean>
              <stddev>0.01</stddev>
            </noise>
          </lidar>
        </sensor>
      </link>

      <!-- joint relationship -->
      <joint name="base_joint" type="fixed">
        <parent>base_link</parent>
        <child>base_footprint</child>
      </joint>

      <joint name="left_wheel_joint" type="revolute">
        <parent>base_link</parent>
        <child>left_wheel_link</child>
        <axis>
          <xyz>0 0 1</xyz>
          <limit>
            <lower>-1.79769e+308</lower>
            <upper>1.79769e+308</upper>
          </limit>
        </axis>
      </joint>

      <joint name="right_wheel_joint" type="revolute">
        <parent>base_link</parent>
        <child>right_wheel_link</child>
        <axis>
          <xyz>0 0 1</xyz>
          <limit>
            <lower>-1.79769e+308</lower>
            <upper>1.79769e+308</upper>
          </limit>
        </axis>
      </joint>

      <joint name="left_front_joint" type="revolute">
        <parent>base_link</parent>
        <child>left_front_link</child>
        <axis>
          <xyz>0 0 1</xyz>
          <limit>
            <lower>-1.79769e+308</lower>
            <upper>1.79769e+308</upper>
          </limit>
        </axis>
      </joint>

      <joint name="right_front_joint" type="revolute">
        <parent>base_link</parent>
        <child>right_front_link</child>
        <axis>
          <xyz>0 0 1</xyz>
          <limit>
            <lower>-1.79769e+308</lower>
            <upper>1.79769e+308</upper>
          </limit>
        </axis>
      </joint>

      <joint name="camera_joint" type="fixed">
        <parent>base_link</parent>
        <child>camera_link</child>
      </joint>

      <joint name="camera_rgb_joint" type="fixed">
        <parent>camera_link</parent>
        <child>camera_rgb_frame</child>
      </joint>

      <joint name="lidar_joint" type="fixed">
        <parent>base_link</parent>
        <child>base_scan</child>
      </joint>

      <plugin
        filename="ignition-gazebo-mecanum-drive-system"
        name="ignition::gazebo::systems::MecanumDrive">
        <front_left_joint>left_front_joint</front_left_joint>
        <front_right_joint>right_front_joint</front_right_joint>
        <back_left_joint>left_wheel_joint</back_left_joint>
        <back_right_joint>right_wheel_joint</back_right_joint>
        <wheel_separation>0.195</wheel_separation>
        <wheelbase>0.17</wheelbase>
        <wheel_radius>0.0375</wheel_radius>
        <min_acceleration>-1</min_acceleration>
        <max_acceleration>1</max_acceleration>
      </plugin>

      <plugin filename="ignition-gazebo-joint-state-publisher-system"
        name="ignition::gazebo::systems::JointStatePublisher">
        <topic>joint_states</topic>
        <joint_name>left_front_joint</joint_name>
        <joint_name>right_front_joint</joint_name>
        <joint_name>left_wheel_joint</joint_name>
        <joint_name>right_wheel_joint</joint_name>
      </plugin>

    </model>
  </world>
</sdf>